Workbook

Sheet README
A1: Coming soon!
A2: Substrate characterization: all influent characterization. In green, from measurments, in yellow calculations (in the "key" it is specified if they come from measurement or literature values), in red values taken from literature.
A3: SteadyState: calculation based on s.Antonio reactor as simulated in Modelica and real measurments of substrates characteristics. COD/VS is based on Modelica conversions (NB error in composite COD/VS calculation to be fixed)

Sheet Substrate characterization
A1: From literature (see "Feedstock.xlsx") | D1: TS | E1: VS/TS | F1: VS/TS_literature | G1: COD | H1: COD_calc_literature | I1: COD/VS_literature | J1: VFA | K1: VFA_literature | L1: BMPexp | M1: BD | N1: TN | O1: Tnsol | P1: PR | Q1: LI | R1: Cellulose | S1: Hemicellulose | T1: Lignin | U1: Starch/NFC | V1: Non-fibrous CH | W1: Sugars | X1: CH | Y1: RF | Z1: Mass balance_literature | AA1: PR_literature | AB1: LI_literature | AC1: Cellulose_literature | AD1: Hemicellulose_literature | AE1: Lignin_literature | AF1: Starch/NFC_literature | AG1: Non-fibrous CH_literature | AH1: Sugars_literature | AI1: CH_literature | AJ1: RF_literature | AK1: Mass balance_literature | AL1: Cellulose BD | AM1: Carbohydrates | AN1: Protein BD | AO1: Lipids BD | AP1: VS BD | AQ1: TS | AR1: VS | AS1: pH | AT1: Alk | AU1: N-NH4 | AV1: P-PO4 | AW1: CODs | AX1: Ca | AY1: Mg | AZ1: Acetate | BA1: Propinate | BB1: Butirate | BC1: Valerate | BD1: S_su | BE1: S_aa | BF1: S_fa | BG1: VS BD (from BMP) | BH1: S_i | BI1: BMPexp | BJ1: BMP | BK1: BMP | BL1: BMP | BM1: BMPth | BN1: BMPth | BO1: BMPth | BP1: BMPth | BQ1: Xi | BR1: Xpr | BS1: Xli | BT1: Xch | BU1: Xlig | BV1: Xi | BW1: Xpr | BX1: Xli | BY1: Xch | BZ1: COD/VS
A2: Calculation | D2: g/kg | E2: % | F2: % | G2: g/kg | H2: g/kg | K2: %TS | L2: NmLch4/gVS | M2: gCOD_BD/g_COD | N2: gN/kg | O2: gN/kg | P2: %TS | Q2: %TS | R2: %TS | S2: %TS | T2: %TS | U2: %TS | V2: %TS | W2: %TS | X2: %TS | Y2: %TS | AA2: %TS | AB2: %TS | AC2: %TS | AD2: %TS | AE2: %TS | AF2: %TS | AG2: %TS | AH2: %TS | AI2: %TS | AJ2: %TS | AL2: % | AM2: % | AN2: % | AO2: % | AP2: % | AQ2: g/kg | AR2: g/kg | AS2: - | AT2: mgCaCO3/L | AU2: mgN/L | AV2: mgP/L | AW2: mgCOD/L | AX2: mol/L | AY2: mol/L | AZ2: gCOD/L | BA2: gCOD/L | BB2: gCOD/L | BC2: gCOD/L | BD2: gCOD/L | BE2: gCOD/L | BF2: gCOD/L | BG2: % | BH2: gCOD/L | BI2: NmLch4/gVS | BJ2: NmLch4/gVS | BK2: NmLch4/gVS | BL2: NmLch4/gVS | BM2: NmL gas/gVS | BN2: NmLch4/gVS | BO2: NmLch4/gVS | BP2: NmLch4/gCOD | BQ2: gCOD/L | BR2: gCOD/L | BS2: gCOD/L | BT2: gCOD/L | BU2: gCOD/L | BV2: gCOD/gVS | BW2: gCOD/gVS | BX2: gCOD/gVS | BY2: gCOD/gVS
A3: From measurments | R3: ADF-ADL | S3: NDF-ADF | T3: ADL | U3: RF+NfE-NDF | V3: Sugars+Starch+Pectines+Organic Acids | X3: RF+NfE | AC3: ADF-ADL | AD3: NDF-ADF | AE3: ADL | AF3: RF+NfE-NDF | AG3: Sugars+Starch+Pectines+Organic Acids | AI3: RF+NfE | AM3: Weissbach e Weinrich. FOM = frazione digeribile dal rumine + estrezione di origine endogena | AZ3: 1.07 | BA3: 1.51 | BB3: 1.82 | BC3: 2.04 | BD3: 1.07 | BE3: 1.53 | BF3: 2.87 | BN3: 5% for bacterial growth. 7% for C5H9O3N Triolo 2011 | BR3: =32*(AA4+AA5/4-3*AA6/4-AA7/2)/($AA$4*12+$AA$5+$AA$6*14+$AA$7*16) -> 1.5303551 | BS3: =32*(AB4+AB5/4-3*AB6/4-AB7/2)/($AB$4*12+$AB$5+$AB$6*14+$AB$7*16) -> 2.8784119 | BT3: =32*(AI4+AI5/4-3*AI6/4-AI7/2)/($AI$4*12+$AI$5+$AI$6*14+$AI$7*16) -> 1.1851852 | BU3: 1.37
B4: C | C4: mol/mol | D4: 12 | P4: 4 | Q4: 51 | T4: 10 | W4: 6 | X4: 6 | AA4: 4 | AB4: 51 | AE4: 10 | AH4: 6 | AI4: 6 | BJ4: PR | BK4: =1000*22.4*(AA4/2+AA5/8-AA7/4-3*AA6/8)/(AA4*12+AA5+AA6*14+AA7*16) -> 535.62428 | BL4: =1000*22.4*(AA4/2-AA5/8+AA7/4+3*AA6/8)/(AA4*12+AA5+AA6*14+AA7*16) -> 490.72165 | BM4: =BK4/(BK4+BL4) -> 0.521875 | BN4: =1000*22.4*(AA4/2+AA5/8-AA7/4-3*AA6/8-0.05*5/2)/(AA4*12+AA5+AA6*14+AA7*16) -> 503.55097 | BO4: =BK4/$BR$3 -> 350 | BP4: =BN4/$BR$3 -> 329.04192 | BR4: =AA4/($AA$4*12+$AA$5+$AA$6*14+$AA$7*16)/$BR$3 -> 0.02994012 | BS4: =AB4/($AB$4*12+$AB$5+$AB$6*14+$AB$7*16)/$BS$3 -> 0.021982759 | BT4: =AI4/($AI$4*12+$AI$5+$AI$6*14+$AI$7*16)/$BT$3 -> 0.03125
B5: H | C5: mol/mol | D5: 1 | P5: 6.1 | Q5: 98 | T5: 13 | W5: 12 | X5: 10 | AA5: 6.1 | AB5: 98 | AE5: 13 | AH5: 12 | AI5: 10 | BJ5: LI | BK5: =1000*22.4*(AB4/2+AB5/8-AB7/4-3*AB6/8)/(AB4*12+AB5+AB6*14+AB7*16) -> 1007.4442 | BL5: =1000*22.4*(AB4/2-AB5/8+AB7/4+3*AB6/8)/(AB4*12+AB5+AB6*14+AB7*16) -> 409.92556 | BM5: =BK5/(BK5+BL5) -> 0.71078431 | BN5: =1000*22.4*(AB4/2+AB5/8-AB7/4-3*AB6/8-0.05*5/2)/(AB4*12+AB5+AB6*14+AB7*16) -> 1003.9702 | BO5: =BK5/$BS$3 -> 350 | BP5: =BN5/$BS$3 -> 348.7931 | BR5: =AA5/($AA$4*12+$AA$5+$AA$6*14+$AA$7*16)/$BR$3 -> 0.045658683 | BS5: =AB5/($AB$4*12+$AB$5+$AB$6*14+$AB$7*16)/$BS$3 -> 0.042241379 | BT5: =AI5/($AI$4*12+$AI$5+$AI$6*14+$AI$7*16)/$BT$3 -> 0.052083333
B6: N | C6: mol/mol | D6: 14 | P6: 1 | Q6: 0 | T6: 0 | W6: 0 | X6: 0 | AA6: 1 | AB6: 0 | AE6: 0 | AH6: 0 | AI6: 0 | BJ6: CH | BK6: =1000*22.4*(AI4/2+AI5/8-AI7/4-3*AI6/8)/(AI4*12+AI5+AI6*14+AI7*16) -> 414.81481 | BL6: =1000*22.4*(AI4/2-AI5/8+AI7/4+3*AI6/8)/(AI4*12+AI5+AI6*14+AI7*16) -> 414.81481 | BM6: =BK6/(BK6+BL6) -> 0.5 | BN6: =1000*22.4*(AI4/2+AI5/8-AI7/4-3*AI6/8-0.05*5/2)/(AI4*12+AI5+AI6*14+AI7*16) -> 397.53086 | BO6: =BK6/$BT$3 -> 350 | BP6: =BN6/$BT$3 -> 335.41667 | BR6: =AA6/($AA$4*12+$AA$5+$AA$6*14+$AA$7*16)/$BR$3 -> 0.0074850299 | BS6: =AB6/($AB$4*12+$AB$5+$AB$6*14+$AB$7*16)/$BS$3 -> 0 | BT6: =AI6/($AI$4*12+$AI$5+$AI$6*14+$AI$7*16)/$BT$3 -> 0
B7: O | C7: mol/mol | D7: 12 | P7: 1.2 | Q7: 6 | T7: 3 | W7: 6 | X7: 5 | AA7: 1.2 | AB7: 6 | AE7: 3 | AH7: 6 | AI7: 5 | AM7: 3.5 | AN7: 2 | AO7: 0.5 | BR7: =AA7/($AA$4*12+$AA$5+$AA$6*14+$AA$7*16)/$BR$3 -> 0.0089820359 | BS7: =AB7/($AB$4*12+$AB$5+$AB$6*14+$AB$7*16)/$BS$3 -> 0.0025862069 | BT7: =AI7/($AI$4*12+$AI$5+$AI$6*14+$AI$7*16)/$BT$3 -> 0.026041667
A8: Nota: Campionamento il 10/07 da s.Antonio post-fermentatore. Post-fermentatore non funziona la linea gas | B8: 45117 | C8: Digestate s.Antonio | D8: 87.4 | E8: 77.2 | H8: =(AH8*$AZ$3+(AI8-AH8-AE8)*$BT$3+$BS$3*AB8+$BR$3*AA8+K8*$AZ$3+AE8*$BU$3)*D8/100 -> 0 | L8: 124 | M8: =L8/I8/330 -> #DIV/0! | Z8: =E8-P8-Q8-X8-J8 -> 77.2 | AK8: =F8-AA8-AB8-AI8 -> 0 | AL8: 28 | AM8: 43 | AN8: =204/279*100 -> 73.11828 | AO8: =26/52*100 -> 50 | AP8: =IF(D8<150,47,56) -> 47 | AQ8: =D8 -> 87.4 | AR8: =E8*D8/100 -> 67.4728 | AS8: 7.4 | AT8: =2*AVERAGE(9209,9090) -> 18299 | AU8: =23.7*100 -> 2370 | AW8: =190*100 -> 19000 | BJ8: =AP8/100*BO8 -> 0 | BK8: =(AA8*AN8/100*0.496+AB8*AO8/100*1.014+AI8*AM8/100*0.415)/E8*1000 -> 0 | BL8: =(0.5495*AN8/100*AA8+0.415*AF8+0.383*AH8+0.948*AB8+0.373*(AG8-AF8)+(AM8/100*AI8-AF8)*0.415)/E8*1000 -> 0 | BM8: =(AA8*0.7+AB8*1.25+AI8*0.79)/E8*1000 -> 0 | BN8: =(AA8*0.7*0.71+AB8*1.25*0.68+AI8*0.79*0.5)/E8*1000 -> 0 | BO8: =(AA8*0.496+AB8*1.014+AI8*0.415)/E8*1000 -> 0 | BP8: =IF(H8="","",BO8/(H8/(D8*E8/100))) -> #DIV/0! | BQ8: =D8/100*(((100-AM8)/100*AI8*$BT$3)+((100-AN8)/100*AA8*$BR$3)+((100-AO8)/100*AB8*$BS$3)) -> 0 | BR8: =AA8*D8/100*AN8/100*$BR$3 -> 0 | BS8: =AB8*D8/100*AO8/100*$BS$3 -> 0 | BT8: =AI8*D8/100*AM8/100*$BT$3 -> 0 | BV8: =BQ8/(D8*E8/100) -> 0 | BW8: =BR8/(D8*E8/100) -> 0 | BX8: =BS8/(D8*E8/100) -> 0 | BY8: =BT8/(D8*E8/100) -> 0 | BZ8: =G8/(D8*E8)/10 -> 0
A9: Nota: 19/10/2023 COD/VS il calculated from literature composition | B9: 45117 | C9: Tomato | D9: 41.5 | E9: 86.9 | H9: =(AH9*$AZ$3+(AI9-AH9-AE9)*$BT$3+$BS$3*AB9+$BR$3*AA9+K9*$AZ$3+AE9*$BU$3)*D9/100 -> 0 | L9: 379 | M9: =L9/I9/330 -> #DIV/0! | Z9: =E9-P9-Q9-X9-J9 -> 86.9 | AK9: =F9-AA9-AB9-AI9 -> 0 | AL9: 28 | AM9: =100*(AI9*10-(35+0.47*AJ9*10+0.00104*(AJ9*10)^2)+35)/(AI9*10) -> #DIV/0! | AN9: =100*(AA9*10-36+20)/(AA9*10) -> #DIV/0! | AO9: =100*(AB9*10-5+5)/(AB9*10) -> #DIV/0! | AP9: =(AN9*AA9+AM9*AI9+AO9*AB9)/E9 -> #DIV/0! | AQ9: =D9 -> 41.5 | AR9: =E9*D9/100 -> 36.0635 | BJ9: =AP9/100*BO9 -> #DIV/0! | BK9: =(AA9*AN9/100*0.496+AB9*AO9/100*1.014+AI9*AM9/100*0.415)/E9*1000 -> #DIV/0! | BL9: =(0.5495*AN9/100*AA9+0.415*AF9+0.383*AH9+0.948*AB9+0.373*(AG9-AF9)+(AM9/100*AI9-AF9)*0.415)/E9*1000 -> #DIV/0! | BM9: =(AA9*0.7+AB9*1.25+AI9*0.79)/E9*1000 -> 0 | BN9: =(AA9*0.7*0.71+AB9*1.25*0.68+AI9*0.79*0.5)/E9*1000 -> 0 | BO9: =(AA9*0.496+AB9*1.014+AI9*0.415)/E9*1000 -> 0 | BP9: =IF(H9="","",BO9/(H9/(D9*E9/100))) -> #DIV/0! | BQ9: =G9-BR9-BS9-BT9 -> 0 | BR9: =$BR$3*AA9*$AN$8/100*D9/100 -> 0 | BS9: =$BS$3*$AO$8/100*AB9*D9/100 -> 0 | BT9: =$BT$3*($AL$8/100*AC9+AD9+AF9)/100*D9 -> 0 | BV9: =BQ9/(D9*E9/100) -> 0 | BW9: =BR9/(D9*E9/100) -> 0 | BX9: =BS9/(D9*E9/100) -> 0 | BY9: =BT9/(D9*E9/100) -> 0 | BZ9: =G9/(D9*E9)/10 -> 0
A10: Nota: Cremona project TS are 90 g/L and 340 g/L for cow slurry and maize silage respectively | B10: 45117 | C10: Egg pasta | D10: 672.2 | E10: 99 | F10: 99 | H10: =(AH10*$AZ$3+(AI10-AH10-AE10)*$BT$3+$BS$3*AB10+$BR$3*AA10+K10*$AZ$3+AE10*$BU$3)*D10/100 -> 905.46329 | I10: =H10/(F10*D10/100) -> 1.3606209 | L10: 361 | M10: =L10/I10/330 -> 0.80400013 | P10: =AA10*$E$10/$F$10 -> 17.809439 | Q10: =AB10*$E$10/$F$10 -> 6.2333037 | R10: =AC10*$E$10/$F$10 -> 0 | S10: =AD10*$E$10/$F$10 -> 3.45 | T10: =AE10*$E$10/$F$10 -> 0 | U10: =AF10*$E$10/$F$10 -> 69.456812 | V10: =AG10*$E$10/$F$10 -> 72.350846 | W10: =AH10*$E$10/$F$10 -> 2.8940338 | X10: =AI10*$E$10/$F$10 -> 75.800846 | Z10: =E10-P10-Q10-X10-J10 -> -0.8435886 | AA10: 17.809439 | AB10: 6.2333037 | AD10: 3.45 | AF10: 69.456812 | AG10: 72.350846 | AH10: 2.8940338 | AI10: =SUM(AC10:AF10,AH10) -> 75.800846 | AK10: =F10-AA10-AB10-AI10-K10 -> -0.8435886 | BZ10: =G10/(D10*E10)/10 -> 0
A11: Nota: dati da s.Antonio 2022 cow slurry and maize silage TS between 60-80 g/L and 330-390 g/L respectively. Semoline 478 g/L. | B11: 45117 | C11: Farinaccio di frumento | H11: =(AH11*$AZ$3+(AI11-AH11-AE11)*$BT$3+$BS$3*AB11+$BR$3*AA11+K11*$AZ$3+AE11*$BU$3)*D11/100 -> 0 | Z11: =E11-P11-Q11-X11-J11 -> 0 | AK11: =F11-AA11-AB11-AI11-K11 -> 0 | BZ11: =G11/(D11*E11)/10 -> #DIV/0!
A12: Nota: add data from BTS and Gelosa? | B12: 45117 | C12: Semoline | D12: 466.2 | E12: 83.7 | F12: 83.7 | H12: =(AH12*$AZ$3+(AI12-AH12-AE12)*$BT$3+$BS$3*AB12+$BR$3*AA12+K12*$AZ$3+AE12*$BU$3)*D12/100 -> 500.49103 | I12: =H12/(F12*D12/100) -> 1.2826217 | J12: =K12*$E$13/$F$13 -> 0 | K12: 0 | L12: 346 | M12: =L12/I12/330 -> 0.8174545 | P12: =AA12*$E$12/$F$12 -> 13.608924 | Q12: =AB12*$E$12/$F$12 -> 2.2511002 | R12: =AC12*$E$12/$F$12 -> 5.6993765 | S12: =AD12*$E$12/$F$12 -> 1.5655379 | T12: =AE12*$E$12/$F$12 -> 0 | U12: =AF12*$E$12/$F$12 -> 57.505379 | V12: =AG12*$E$12/$F$12 -> 57.505379 | W12: =AH12*$E$12/$F$12 -> 3.0696822 | X12: =AI12*$E$12/$F$12 -> 67.839976 | Z12: =E12-P12-Q12-X12-J12 -> -1.4210855e-14 | AA12: 13.608924 | AB12: 2.2511002 | AC12: 5.6993765 | AD12: 1.5655379 | AE12: 0 | AF12: 57.505379 | AG12: 57.505379 | AH12: 3.0696822 | AI12: =SUM(AC12:AF12,AH12) -> 67.839976 | AK12: =F12-AA12-AB12-AI12-K12 -> -1.4210855e-14 | BZ12: =G12/(D12*E12)/10 -> 0
B13: 45160 | C13: Maize silage | D13: 278.3 | E13: 95.9 | F13: 96.5 | H13: =(AH13*$AZ$3+(AI13-AH13-AE13)*$BT$3+$BS$3*AB13+$BR$3*AA13+K13*$AZ$3+AE13*$BU$3)*D13/100 -> 337.42687 | I13: =H13/(F13*D13/100) -> 1.2564325 | J13: =K13*$E$13/$F$13 -> 2.9714093 | K13: 2.99 | L13: 344 | M13: =L13/I13/330 -> 0.82966994 | P13: =AA13*$E$13/$F$13 -> 6.8570984 | Q13: =AB13*$E$13/$F$13 -> 2.5838342 | R13: =AC13*$E$13/$F$13 -> 22.161347 | S13: =AD13*$E$13/$F$13 -> 14.608601 | T13: =AE13*$E$13/$F$13 -> 1.6894301 | U13: =AF13*$E$13/$F$13 -> 44.322694 | V13: =AG13*$E$13/$F$13 -> 0 | W13: =AH13*$E$13/$F$13 -> 0.89440415 | X13: =AI13*$E$13/$F$13 -> 83.676477 | Z13: =E13-P13-Q13-X13-J13 -> -0.18881865 | AA13: 6.9 | AB13: 2.6 | AC13: 22.3 | AD13: 14.7 | AE13: 1.7 | AF13: =31.2+13.4 -> 44.6 | AH13: 0.9 | AI13: =SUM(AC13:AF13,AH13) -> 84.2 | AK13: =F13-AA13-AB13-AI13-K13 -> -0.19 | BZ13: =G13/(D13*E13)/10 -> 0
B14: 45160 | C14: Cow slurry s.Antonio | D14: 48.4 | E14: 76 | F14: 80 | H14: =(AH14*$AZ$3+(AI14-AH14-AE14)*$BT$3+$BS$3*AB14+$BR$3*AA14+K14*$AZ$3+AE14*$BU$3)*D14/100 -> 59.423395 | I14: =H14/(F14*D14/100) -> 1.5346951 | J14: =K14*$E$14/$F$14 -> 9.3385 | K14: 9.83 | L14: 273 | M14: =L14/I14/330 -> 0.53904695 | P14: =AA14*$E$14/$F$14 -> 16.055 | Q14: =AB14*$E$14/$F$14 -> 5.035 | R14: =AC14*$E$14/$F$14 -> 17.29 | S14: =AD14*$E$14/$F$14 -> 10.545 | T14: =AE14*$E$14/$F$14 -> 14.155 | U14: =AF14*$E$14/$F$14 -> 12.825 | V14: =AG14*$E$14/$F$14 -> 0 | W14: =AH14*$E$14/$F$14 -> 0 | X14: =AI14*$E$14/$F$14 -> 54.815 | Z14: =E14-P14-Q14-X14-J14 -> -9.2435 | AA14: 16.9 | AB14: 5.3 | AC14: 18.2 | AD14: 11.1 | AE14: 14.9 | AF14: 13.5 | AI14: =SUM(AC14:AF14,AH14) -> 57.7 | AK14: =F14-AA14-AB14-AI14-K14 -> -9.73 | BZ14: =G14/(D14*E14)/10 -> 0
B15: 45160 | C15: Liquid digestate s.Antonio | D15: 48.1 | E15: 61.4 | H15: =(AH15*$AZ$3+(AI15-AH15-AE15)*$BT$3+$BS$3*AB15+$BR$3*AA15+K15*$AZ$3+AE15*$BU$3)*D15/100 -> 0 | L15: 60 | M15: =L15/I15/330 -> #DIV/0! | Z15: =E15-P15-Q15-X15-J15 -> 61.4 | AK15: =F15-AA15-AB15-AI15 -> 0 | BZ15: =G15/(D15*E15)/10 -> 0
B16: 45160 | C16: Tomato souce | D16: 76.9 | E16: 85.4 | F16: 95 | H16: =(AH16*$AZ$3+(AI16-AH16-AE16)*$BT$3+$BS$3*AB16+$BR$3*AA16+K16*$AZ$3+AE16*$BU$3)*D16/100 -> 106.27061 | I16: =H16/(F16*D16/100) -> 1.4546658 | J16: =K16*$E$16/$F$16 -> 1.6720421 | K16: 1.86 | L16: 383 | M16: =L16/I16/330 -> 0.79785066 | P16: =AA16*$E$16/$F$16 -> 7.2642212 | Q16: =AB16*$E$16/$F$16 -> 13.620415 | R16: =AC16*$E$16/$F$16 -> 0 | S16: =AD16*$E$16/$F$16 -> 27.238105 | T16: =AE16*$E$16/$F$16 -> 0 | U16: =AF16*$E$16/$F$16 -> 0 | V16: =AG16*$E$16/$F$16 -> 0 | W16: =AH16*$E$16/$F$16 -> 37.229133 | X16: =AI16*$E$16/$F$16 -> 64.467239 | Z16: =E16-P16-Q16-X16-J16 -> -1.6239166 | AA16: =0.8/(1.5+5.5+1.6+0.8+0.5)*100 -> 8.0808081 | AB16: =1.5/(1.5+5.5+1.6+0.8+0.5)*100 -> 15.151515 | AD16: 30.3 | AH16: =4.1/(1.5+5.5+1.6+0.8+0.5)*100 -> 41.414141 | AI16: =SUM(AC16:AF16,AH16) -> 71.714141 | AK16: =F16-AA16-AB16-AI16-K16 -> -1.8064646 | BZ16: =G16/(D16*E16)/10 -> 0
B17: 45160 | C17: Tomato souce | D17: 76.9 | E17: 85.4 | F17: =(1.3+5.3)/(0.4+1.3+5.3)*100 -> 94.285714 | J17: =K17*$E$17/$F$17 -> 1.6847091 | K17: 1.86 | P17: =AA17*$E$17/$F$17 -> 16.821212 | Q17: =AB17*$E$17/$F$17 -> 0 | R17: =AC17*$E$17/$F$17 -> 0 | S17: =AD17*$E$17/$F$17 -> 28.803091 | T17: =AE17*$E$17/$F$17 -> 0 | U17: =AF17*$E$17/$F$17 -> 0 | V17: =AG17*$E$17/$F$17 -> 0 | W17: =AH17*$E$17/$F$17 -> 39.775697 | X17: =AI17*$E$17/$F$17 -> 68.578788 | Z17: =E17-P17-Q17-X17-J17 -> -1.6847091 | AA17: =1.3/((0.4+1.3+5.3))*100 -> 18.571429 | AD17: =5.3*0.42/((0.4+1.3+5.3))*100 -> 31.8 | AH17: =5.3*(1-0.42)/((0.4+1.3+5.3))*100 -> 43.914286 | AI17: =SUM(AC17:AF17,AH17) -> 75.714286 | AK17: =F17-AA17-AB17-AI17-K17 -> -1.86 | BZ17: =G17/(D17*E17)/10 -> 0
B18: 45160 | C18: Semoline? | BZ18: =G18/(D18*E18)/10 -> #DIV/0!
B19: 45219 | C19: Liquid digestate s.Antonio | D19: =(6.0607-4.6455)/(29.6598-4.6455)*1000 -> 56.575639 | E19: =(D19-(5.1238-4.6455)/(29.6598-4.6455)*1000)/D19*100 -> 66.202657 | AS19: 8.12 | AT19: 21097.76 | AU19: 2260 | AV19: 94.4 | BZ19: =G19/(D19*E19)/10 -> 0
B20: 45219 | C20: Liquid digestate s.Antonio | D20: =(6.1667-4.3933)/(35.7883-4.3933)*1000 -> 56.486702 | E20: =(D20-(4.9968-4.3933)/(35.7883-4.3933)*1000)/D20*100 -> 65.969324 | BZ20: =G20/(D20*E20)/10 -> 0
B21: 45222 | C21: Cow slurry s.Antonio | D21: =(6.128-4.407)/(30.4458-4.407)*1000 -> 66.093676 | E21: =(D21-(4.7656-4.407)/(30.4458-4.407)*1000)/D21*100 -> 79.163277 | BZ21: =G21/(D21*E21)/10 -> 0
B22: 45222 | C22: Cow slurry s.Antonio | D22: =(6.0943-4.4178)/(29.4099-4.4178)*1000 -> 67.081198 | E22: =(D22-(4.7542-4.4178)/(29.4099-4.4178)*1000)/D22*100 -> 79.934387 | BZ22: =G22/(D22*E22)/10 -> 0
B23: 45224 | C23: Maize silage | D23: =(5.9775-4.4396)/(10.4616-4.4396)*1000 -> 255.38027 | E23: =(D23-(4.5088-4.4396)/(10.4616-4.4396)*1000)/D23*100 -> 95.500358 | AZ23: =(914.8*0.27522-115.4*0.25)/25.22*AZ3 -> 9.4578011 | BA23: =(158.2*0.27522-0*0.25)/25.22*BA3 -> 2.6068638 | BB23: =((12.6+18.3)*0.27522-11*0.25)/25.22*BB3 -> 0.41525862 | BC23: 0 | BD23: =((84.14*0.27522-30.7*0.25)/25.22*BD3) -> 0.65684978 | BZ23: =G23/(D23*E23)/10 -> 0
B24: 45224 | C24: Maize silage | D24: =(6.0368-4.3551)/(10.3591-4.3551)*1000 -> 280.0966 | E24: =(D24-(4.4172-4.3551)/(10.3591-4.3551)*1000)/D24*100 -> 96.307308 | BZ24: =G24/(D24*E24)/10 -> 0
B25: 45224 | C25: Tomato souce | D25: =(5.4239-4.4578)/(17.6867-4.4578)*1000 -> 73.029504 | E25: =(D25-(4.6005-4.4578)/(17.6867-4.4578)*1000)/D25*100 -> 85.229272 | BZ25: =G25/(D25*E25)/10 -> 0
B26: 45224 | C26: Tomato souce | D26: =(5.5463-4.4173)/(19.9584-4.4173)*1000 -> 72.64608 | E26: =(D26-(4.5859-4.4173)/(19.9584-4.4173)*1000)/D26*100 -> 85.06643 | BZ26: =G26/(D26*E26)/10 -> 0
B27: 45233 | C27: Cow slurry s.Antonio | D27: =(6.4514-4.2815)/(42.6476-4.2815)*1000 -> 56.557742 | E27: =(D27-(4.7666-4.2815)/(42.6476-4.2815)*1000)/D27*100 -> 77.644131 | BZ27: =G27/(D27*E27)/10 -> 0
B28: 45233 | C28: Cow slurry s.Antonio | D28: =(6.4404-4.3786)/(40.7965-4.3786)*1000 -> 56.615016 | E28: =(D28-(4.8296-4.3786)/(40.7965-4.3786)*1000)/D28*100 -> 78.125909 | BZ28: =G28/(D28*E28)/10 -> 0
B29: 45233 | C29: "Dig Degas" | D29: 54.101984 | E29: 62.067175 | BZ29: =G29/(D29*E29)/10 -> 0
B30: 45233 | C30: "Dig Degas" | D30: 54.643183 | E30: 62.630749 | BZ30: =G30/(D30*E30)/10 -> 0
B31: 45233 | C31: Liquid digestate s.Antonio after sieving on 18.10 | D31: 55.27746 | E31: 64.920668 | BZ31: =G31/(D31*E31)/10 -> 0
B32: 45233 | C32: Liquid digestate s.Antonio after sieving on 18.10 | D32: 55.464861 | E32: 64.580709 | BZ32: =G32/(D32*E32)/10 -> 0
B33: 45233 | C33: Cow slurry s.Antonio | AS33: 7.68 | AT33: =5800.2*2 -> 11600.4 | AU33: =58.6*20 -> 1172 | AV33: =2.8*20 -> 56 | AW33: =648*20 -> 12960 | AZ33: =AZ3*3059/1000 -> 3.27313 | BA33: =BA3*1331/1000 -> 2.00981 | BB33: =BB3*(140+165)/1000 -> 0.5551 | BC33: =BC3*(191+53)/1000 -> 0.49776 | BZ33: =G33/(D33*E33)/10 -> #DIV/0!
B34: 45245 | C34: Cow slurry s.Antonio | D34: 54.834954 | E34: 78.347922 | BZ34: =G34/(D34*E34)/10 -> 0
B35: 45245 | C35: Cow slurry s.Antonio | D35: 55.008448 | E35: 77.211136 | BZ35: =G35/(D35*E35)/10 -> 0
B36: 45272 | C36: Maize silage | D36: 278.62397 | E36: 95.159255 | AZ36: =(1209.87*0.27522-115.4*0.25)/25.22*AZ3 -> 12.903234 | BA36: =(134.73*0.27522-0*0.25)/25.22*BA3 -> 2.2201185 | BB36: =(13.3*0.27522-11*0.25)/25.22*BB3 -> 0.065700845 | BC36: 0 | BD36: =((153.02*0.27522-30.7*0.25)/25.22*BD3) -> 1.4611382 | BZ36: =G36/(D36*E36)/10 -> 0
B37: 45272 | C37: Maize silage | D37: 248.62515 | E37: 94.389439 | BZ37: =G37/(D37*E37)/10 -> 0
B38: 45272 | C38: Cow slurry s.Antonio | D38: 68.187594 | E38: 80.467317 | BZ38: =G38/(D38*E38)/10 -> 0
B39: 45272 | C39: Cow slurry s.Antonio | D39: 69.637924 | E39: 81.047461 | BZ39: =G39/(D39*E39)/10 -> 0
B40: 45280 | C40: Cow slurry s.Antonio | D40: 46.607672 | E40: 78.343528 | BZ40: =G40/(D40*E40)/10 -> 0
...

Sheet R1 feed
A1: Data | B1: Time | C1: Timestamp | D1: Slurry | E1: Maize | F1: Tomato | G1: Tomato bottle weight | H1: Note | I1: pHs | J1: Slurry VS | K1: Slurry S_COD | L1: Maize S_COD | M1: Tomato S_COD | N1: Slurry COD | O1: Maize COD | P1: Tomato COD | Q1: COD_in | R1: Start Modelica Timestamp
D2: [g] | E2: [g] | F2: [g] | K2: 1.53 | L2: 1.26 | M2: 1.3 | R2: =86400*2+13*3600 -> 219600 | V2: Devo aggiungere 0?
A3: 23/10/2023 | B3: 15:00 | C3: =TEXT(DATEVALUE(A3) + TIMEVALUE(B3), "gg-mm-aaaa hh:mm") -> 23-10-2023 15:00 | D3: =243*2 -> 486 | E3: =61*2 -> 122 | F3: 0 | I3: 1 | J3: =66.4*79.5/100 -> 52.788 | K3: =J3*$K$2 -> 80.76564 | L3: =267.7*95.9/100*$L$2 -> 323.47262 | M3: =72.8*85.1/100*$M$2 -> 80.53864 | N3: =K3*D3/1000 -> 39.252101 | O3: =L3*E3/1000 -> 39.463659 | P3: =M3*F3/1000 -> 0 | Q3: =SUM(N3:P3) -> 78.71576 | R3: =TIMEVALUE(C3) -> 0.625 | S3: =DATEVALUE(A3)-MIN($A$3:$A$68) -> 45222 | T3: =R3*86400 -> 54000 | U3: =S3-MIN($S$3:$S$68) -> 0 | V3: =U3*86400 -> 0 | W3: =V3+T3 -> 54000 | X3: =W3-$R$2 -> -165600 | Y3: =E3 -> 122 | Z3: =D3 -> 486
A4: 25/10/2023 | B4: 15:00 | C4: =TEXT(DATEVALUE(A4) + TIMEVALUE(B4), "gg-mm-aaaa hh:mm") -> 25-10-2023 15:00 | D4: =243*2 -> 486 | E4: =61*2 -> 122 | F4: 0 | H4: Bottle of 300 mL of tomato sauce | I4: 1 | J4: =66.4*79.5/100 -> 52.788 | K4: =J4*$K$2 -> 80.76564 | L4: =267.7*95.9/100*$L$2 -> 323.47262 | M4: =72.8*85.1/100*$M$2 -> 80.53864 | N4: =K4*D4/1000 -> 39.252101 | O4: =L4*E4/1000 -> 39.463659 | P4: =M4*F4/1000 -> 0 | Q4: =SUM(N4:P4) -> 78.71576 | R4: =TIMEVALUE(C4) -> 0.625 | S4: =DATEVALUE(A4)-MIN($A$3:$A$68) -> 45224 | T4: =R4*86400 -> 54000 | U4: =S4-MIN($S$3:$S$68) -> 2 | V4: =U4*86400 -> 172800 | W4: =V4+T4 -> 226800 | X4: =W4-$R$2 -> 7200 | Y4: =E4 -> 122 | Z4: =D4 -> 486
A5: 25/10/2023 | B5: 15:21 | C5: =TEXT(DATEVALUE(A5) + TIMEVALUE(B5), "gg-mm-aaaa hh:mm") -> 25-10-2023 15:21 | F5: 0 | H5: Start weight bottle 976.61 g | J5: =66.4*79.5/100 -> 52.788 | K5: =J5*$K$2 -> 80.76564 | L5: =267.7*95.9/100*$L$2 -> 323.47262 | M5: =72.8*85.1/100*$M$2 -> 80.53864 | N5: =K5*D5/1000 -> 0 | O5: =L5*E5/1000 -> 0 | P5: =M5*F5/1000 -> 0 | Q5: =SUM(N5:P5) -> 0 | R5: =TIMEVALUE(C5) -> 0.63958333 | S5: =DATEVALUE(A5)-MIN($A$3:$A$68) -> 45224 | T5: =R5*86400 -> 55260 | U5: =S5-MIN($S$3:$S$68) -> 2 | V5: =U5*86400 -> 172800 | W5: =V5+T5 -> 228060 | X5: =W5-$R$2 -> 8460 | Y5: =E5 -> 0 | Z5: =D5 -> 0
A6: 25/10/2023 | B6: 15:22 | C6: =TEXT(DATEVALUE(A6) + TIMEVALUE(B6), "gg-mm-aaaa hh:mm") -> 25-10-2023 15:22 | F6: =F5+60*0.166667 -> 10.00002 | J6: =66.4*79.5/100 -> 52.788 | K6: =J6*$K$2 -> 80.76564 | L6: =267.7*95.9/100*$L$2 -> 323.47262 | M6: =72.8*85.1/100*$M$2 -> 80.53864 | N6: =K6*D6/1000 -> 0 | O6: =L6*E6/1000 -> 0 | P6: =M6*F6/1000 -> 0.80538801 | Q6: =SUM(N6:P6) -> 0.80538801 | R6: =TIMEVALUE(C6) -> 0.64027778 | S6: =DATEVALUE(A6)-MIN($A$3:$A$68) -> 45224 | T6: =R6*86400 -> 55320 | U6: =S6-MIN($S$3:$S$68) -> 2 | V6: =U6*86400 -> 172800 | W6: =V6+T6 -> 228120 | X6: =W6-$R$2 -> 8520 | Y6: =E6 -> 0 | Z6: =D6 -> 0
A7: 25/10/2023 | B7: 16:38 | C7: =TEXT(DATEVALUE(A7) + TIMEVALUE(B7), "gg-mm-aaaa hh:mm") -> 25-10-2023 16:38 | F7: =F6 -> 10.00002 | H7: I set it wrong: 1 min/1.5 hours. Now modified. From now on R1 and R2 are going to be mixed and fed with tomato almost at the same timestamp | J7: =66.4*79.5/100 -> 52.788 | K7: =J7*$K$2 -> 80.76564 | L7: =267.7*95.9/100*$L$2 -> 323.47262 | M7: =72.8*85.1/100*$M$2 -> 80.53864 | N7: =K7*D7/1000 -> 0 | O7: =L7*E7/1000 -> 0 | P7: =M7*F7/1000 -> 0.80538801 | Q7: =SUM(N7:P7) -> 0.80538801 | R7: =TIMEVALUE(C7) -> 0.69305556 | S7: =DATEVALUE(A7)-MIN($A$3:$A$68) -> 45224 | T7: =R7*86400 -> 59880 | U7: =S7-MIN($S$3:$S$68) -> 2 | V7: =U7*86400 -> 172800 | W7: =V7+T7 -> 232680 | X7: =W7-$R$2 -> 13080 | Y7: =E7 -> 0 | Z7: =D7 -> 0
A8: 27/10/2023 | B8: 10:50 | C8: =TEXT(DATEVALUE(A8) + TIMEVALUE(B8), "gg-mm-aaaa hh:mm") -> 27-10-2023 10:50 | D8: 730 | E8: 183 | F8: 0 | H8: the weight of the tomato bottle before filling: 805,88g the weight of the tomato bottle after filling: 1183,40g | I8: 1 | J8: =66.4*79.5/100 -> 52.788 | K8: =J8*$K$2 -> 80.76564 | L8: =267.7*95.9/100*$L$2 -> 323.47262 | M8: =72.8*85.1/100*$M$2 -> 80.53864 | N8: =K8*D8/1000 -> 58.958917 | O8: =L8*E8/1000 -> 59.195489 | P8: =M8*F8/1000 -> 0 | Q8: =SUM(N8:P8) -> 118.15441 | R8: =TIMEVALUE(C8) -> 0.45138889 | S8: =DATEVALUE(A8)-MIN($A$3:$A$68) -> 45226 | T8: =R8*86400 -> 39000 | U8: =S8-MIN($S$3:$S$68) -> 4 | V8: =U8*86400 -> 345600 | W8: =V8+T8 -> 384600 | X8: =W8-$R$2 -> 165000 | Y8: =E8 -> 183 | Z8: =D8 -> 730
A9: 30/10/2023 | B9: 11:15 | C9: =TEXT(DATEVALUE(A9) + TIMEVALUE(B9), "gg-mm-aaaa hh:mm") -> 30-10-2023 11:15 | F9: ? | H9: Acetate spike fed with pumps (480 mL of 50gCOD/L solution). Forgot to weight tomato bottle…MOLD! | J9: =56.6*77.9/100 -> 44.0914 | K9: =J9*$K$2 -> 67.459842 | L9: =267.7*95.9/100*$L$2 -> 323.47262 | M9: =72.8*85.1/100*$M$2 -> 80.53864 | N9: =K9*D9/1000 -> 0 | O9: =L9*E9/1000 -> 0 | P9: =M9*F9/1000 -> #VALUE! | Q9: =SUM(N9:P9) -> #VALUE! | R9: =TIMEVALUE(C9) -> 0.46875 | S9: =DATEVALUE(A9)-MIN($A$3:$A$68) -> 45229 | T9: =R9*86400 -> 40500 | U9: =S9-MIN($S$3:$S$68) -> 7 | V9: =U9*86400 -> 604800 | W9: =V9+T9 -> 645300 | X9: =W9-$R$2 -> 425700 | Y9: =E9 -> 0 | Z9: =D9 -> 0
A10: 03/11/2023 | B10: 10:14 | C10: =TEXT(DATEVALUE(A10) + TIMEVALUE(B10), "gg-mm-aaaa hh:mm") -> 03-11-2023 10:14 | D10: 730 | E10: 183 | F10: 0 | G10: 1088.98 | H10: weight of empty clean tomato bottle: 707,55g the weight of tomato bottle after filling: 1088,98g. PLEASE NOTE that we didnt write down the exact time for feeding but it was between 10:00 ana 10:30 | I10: 1 | J10: =56.6*77.9/100 -> 44.0914 | K10: =J10*$K$2 -> 67.459842 | L10: =267.7*95.9/100*$L$2 -> 323.47262 | M10: =72.8*85.1/100*$M$2 -> 80.53864 | N10: =K10*D10/1000 -> 49.245685 | O10: =L10*E10/1000 -> 59.195489 | P10: =M10*F10/1000 -> 0 | Q10: =SUM(N10:P10) -> 108.44117 | R10: =TIMEVALUE(C10) -> 0.42638889 | S10: =DATEVALUE(A10)-MIN($A$3:$A$68) -> 45233 | T10: =R10*86400 -> 36840 | U10: =S10-MIN($S$3:$S$68) -> 11 | V10: =U10*86400 -> 950400 | W10: =V10+T10 -> 987240 | X10: =W10-$R$2 -> 767640 | Y10: =E10 -> 183 | Z10: =D10 -> 730
A11: 06/11/2023 | B11: 10:00 | C11: =TEXT(DATEVALUE(A11) + TIMEVALUE(B11), "gg-mm-aaaa hh:mm") -> 06-11-2023 10:00 | D11: 0 | E11: 0 | F11: =G10-G11 -> 249.22 | G11: 839.76 | I11: 1 | J11: =56.6*77.9/100 -> 44.0914 | K11: =J11*$K$2 -> 67.459842 | L11: =267.7*95.9/100*$L$2 -> 323.47262 | M11: =72.8*85.1/100*$M$2 -> 80.53864 | N11: =K11*D11/1000 -> 0 | O11: =L11*E11/1000 -> 0 | P11: =M11*F11/1000 -> 20.07184 | Q11: =SUM(N11:P11) -> 20.07184 | R11: =TIMEVALUE(C11) -> 0.41666667 | S11: =DATEVALUE(A11)-MIN($A$3:$A$68) -> 45236 | T11: =R11*86400 -> 36000 | U11: =S11-MIN($S$3:$S$68) -> 14 | V11: =U11*86400 -> 1209600 | W11: =V11+T11 -> 1245600 | X11: =W11-$R$2 -> 1026000 | Y11: =E11 -> 0 | Z11: =D11 -> 0
A12: 06/11/2023 | B12: 10:00 | C12: =TEXT(DATEVALUE(A12) + TIMEVALUE(B12), "gg-mm-aaaa hh:mm") -> 06-11-2023 10:00 | G12: 1088.09 | H12: After refill. Then I went in manual mode to refill the tube. At 15:00, the weight was 987.75g. Then, filled it up again. | J12: =56.6*77.9/100 -> 44.0914 | K12: =J12*$K$2 -> 67.459842 | L12: =267.7*95.9/100*$L$2 -> 323.47262 | M12: =72.8*85.1/100*$M$2 -> 80.53864 | N12: =K12*D12/1000 -> 0 | O12: =L12*E12/1000 -> 0 | P12: =M12*F12/1000 -> 0 | Q12: =SUM(N12:P12) -> 0 | R12: =TIMEVALUE(C12) -> 0.41666667 | S12: =DATEVALUE(A12)-MIN($A$3:$A$68) -> 45236 | T12: =R12*86400 -> 36000 | U12: =S12-MIN($S$3:$S$68) -> 14 | V12: =U12*86400 -> 1209600 | W12: =V12+T12 -> 1245600 | X12: =W12-$R$2 -> 1026000 | Y12: =E12 -> 0 | Z12: =D12 -> 0
A13: 06/11/2023 | B13: 15:15 | C13: =TEXT(DATEVALUE(A13) + TIMEVALUE(B13), "gg-mm-aaaa hh:mm") -> 06-11-2023 15:15 | D13: =243*2 -> 486 | E13: =61*2 -> 122 | F13: 0 | G13: 1044.81 | I13: 1 | J13: =56.6*77.9/100 -> 44.0914 | K13: =J13*$K$2 -> 67.459842 | L13: =267.7*95.9/100*$L$2 -> 323.47262 | M13: =72.8*85.1/100*$M$2 -> 80.53864 | N13: =K13*D13/1000 -> 32.785483 | O13: =L13*E13/1000 -> 39.463659 | P13: =M13*F13/1000 -> 0 | Q13: =SUM(N13:P13) -> 72.249143 | R13: =TIMEVALUE(C13) -> 0.63541667 | S13: =DATEVALUE(A13)-MIN($A$3:$A$68) -> 45236 | T13: =R13*86400 -> 54900 | U13: =S13-MIN($S$3:$S$68) -> 14 | V13: =U13*86400 -> 1209600 | W13: =V13+T13 -> 1264500 | X13: =W13-$R$2 -> 1044900 | Y13: =E13 -> 122 | Z13: =D13 -> 486
A14: 08/11/2023 | B14: 11:06 | C14: =TEXT(DATEVALUE(A14) + TIMEVALUE(B14), "gg-mm-aaaa hh:mm") -> 08-11-2023 11:06 | D14: 0 | E14: 0 | F14: =G13-G14 -> 171.66 | G14: 873.15 | H14: Empied, cleaned and refilled, cause there was a starting of fermentation | I14: 1 | J14: =56.6*77.9/100 -> 44.0914 | K14: =J14*$K$2 -> 67.459842 | L14: =267.7*95.9/100*$L$2 -> 323.47262 | M14: =72.8*85.1/100*$M$2 -> 80.53864 | N14: =K14*D14/1000 -> 0 | O14: =L14*E14/1000 -> 0 | P14: =M14*F14/1000 -> 13.825263 | Q14: =SUM(N14:P14) -> 13.825263 | R14: =TIMEVALUE(C14) -> 0.4625 | S14: =DATEVALUE(A14)-MIN($A$3:$A$68) -> 45238 | T14: =R14*86400 -> 39960 | U14: =S14-MIN($S$3:$S$68) -> 16 | V14: =U14*86400 -> 1382400 | W14: =V14+T14 -> 1422360 | X14: =W14-$R$2 -> 1202760 | Y14: =E14 -> 0 | Z14: =D14 -> 0
A15: 08/11/2023 | B15: 11:06 | C15: =TEXT(DATEVALUE(A15) + TIMEVALUE(B15), "gg-mm-aaaa hh:mm") -> 08-11-2023 11:06 | G15: 1099.23 | H15: After refill | J15: =56.6*77.9/100 -> 44.0914 | K15: =J15*$K$2 -> 67.459842 | L15: =267.7*95.9/100*$L$2 -> 323.47262 | M15: =72.8*85.1/100*$M$2 -> 80.53864 | N15: =K15*D15/1000 -> 0 | O15: =L15*E15/1000 -> 0 | P15: =M15*F15/1000 -> 0 | Q15: =SUM(N15:P15) -> 0 | R15: =TIMEVALUE(C15) -> 0.4625 | S15: =DATEVALUE(A15)-MIN($A$3:$A$68) -> 45238 | T15: =R15*86400 -> 39960 | U15: =S15-MIN($S$3:$S$68) -> 16 | V15: =U15*86400 -> 1382400 | W15: =V15+T15 -> 1422360 | X15: =W15-$R$2 -> 1202760 | Y15: =E15 -> 0 | Z15: =D15 -> 0
A16: 08/11/2023 | B16: 15:00 | C16: =TEXT(DATEVALUE(A16) + TIMEVALUE(B16), "gg-mm-aaaa hh:mm") -> 08-11-2023 15:00 | D16: =243*2 -> 486 | E16: =61*2 -> 122 | F16: 0 | I16: 1 | J16: =56.6*77.9/100 -> 44.0914 | K16: =J16*$K$2 -> 67.459842 | L16: =267.7*95.9/100*$L$2 -> 323.47262 | M16: =72.8*85.1/100*$M$2 -> 80.53864 | N16: =K16*D16/1000 -> 32.785483 | O16: =L16*E16/1000 -> 39.463659 | P16: =M16*F16/1000 -> 0 | Q16: =SUM(N16:P16) -> 72.249143 | R16: =TIMEVALUE(C16) -> 0.625 | S16: =DATEVALUE(A16)-MIN($A$3:$A$68) -> 45238 | T16: =R16*86400 -> 54000 | U16: =S16-MIN($S$3:$S$68) -> 16 | V16: =U16*86400 -> 1382400 | W16: =V16+T16 -> 1436400 | X16: =W16-$R$2 -> 1216800 | Y16: =E16 -> 122 | Z16: =D16 -> 486
A17: 08/11/2023 | B17: 17:00 | C17: =TEXT(DATEVALUE(A17) + TIMEVALUE(B17), "gg-mm-aaaa hh:mm") -> 08-11-2023 17:00 | D17: 0 | E17: 0 | F17: =G15-G17 -> 15.71 | G17: 1083.52 | I17: 1 | J17: =56.6*77.9/100 -> 44.0914 | K17: =J17*$K$2 -> 67.459842 | L17: =267.7*95.9/100*$L$2 -> 323.47262 | M17: =72.8*85.1/100*$M$2 -> 80.53864 | N17: =K17*D17/1000 -> 0 | O17: =L17*E17/1000 -> 0 | P17: =M17*F17/1000 -> 1.265262 | Q17: =SUM(N17:P17) -> 1.265262 | R17: =TIMEVALUE(C17) -> 0.70833333 | S17: =DATEVALUE(A17)-MIN($A$3:$A$68) -> 45238 | T17: =R17*86400 -> 61200 | U17: =S17-MIN($S$3:$S$68) -> 16 | V17: =U17*86400 -> 1382400 | W17: =V17+T17 -> 1443600 | X17: =W17-$R$2 -> 1224000 | Y17: =E17 -> 0 | Z17: =D17 -> 0
A18: 10/11/2023 | B18: 09:30 | C18: =TEXT(DATEVALUE(A18) + TIMEVALUE(B18), "gg-mm-aaaa hh:mm") -> 10-11-2023 09:30 | D18: 730 | E18: 183 | F18: 0 | G18: 972.47 | H18: NOTE this is the weight of the tomato bottle before emptying and cleaning | I18: 1 | J18: =56.6*77.9/100 -> 44.0914 | K18: =J18*$K$2 -> 67.459842 | L18: =267.7*95.9/100*$L$2 -> 323.47262 | M18: =72.8*85.1/100*$M$2 -> 80.53864 | N18: =K18*D18/1000 -> 49.245685 | O18: =L18*E18/1000 -> 59.195489 | P18: =M18*F18/1000 -> 0 | Q18: =SUM(N18:P18) -> 108.44117 | R18: =TIMEVALUE(C18) -> 0.39583333 | S18: =DATEVALUE(A18)-MIN($A$3:$A$68) -> 45240 | T18: =R18*86400 -> 34200 | U18: =S18-MIN($S$3:$S$68) -> 18 | V18: =U18*86400 -> 1555200 | W18: =V18+T18 -> 1589400 | X18: =W18-$R$2 -> 1369800 | Y18: =E18 -> 183 | Z18: =D18 -> 730
A19: 10/11/2023 | B19: 11:00 | C19: =TEXT(DATEVALUE(A19) + TIMEVALUE(B19), "gg-mm-aaaa hh:mm") -> 10-11-2023 11:00 | G19: 1219.25 | H19: NOTE: this is the weight of the bottle after emptying, cleaning and disinfecting and refilling with tomato | J19: =56.6*77.9/100 -> 44.0914 | K19: =J19*$K$2 -> 67.459842 | L19: =267.7*95.9/100*$L$2 -> 323.47262 | M19: =72.8*85.1/100*$M$2 -> 80.53864 | N19: =K19*D19/1000 -> 0 | O19: =L19*E19/1000 -> 0 | P19: =M19*F19/1000 -> 0 | Q19: =SUM(N19:P19) -> 0 | R19: =TIMEVALUE(C19) -> 0.45833333 | S19: =DATEVALUE(A19)-MIN($A$3:$A$68) -> 45240 | T19: =R19*86400 -> 39600 | U19: =S19-MIN($S$3:$S$68) -> 18 | V19: =U19*86400 -> 1555200 | W19: =V19+T19 -> 1594800 | X19: =W19-$R$2 -> 1375200 | Y19: =E19 -> 0 | Z19: =D19 -> 0
A20: 13/11/2023 | B20: 10:15 | C20: =TEXT(DATEVALUE(A20) + TIMEVALUE(B20), "gg-mm-aaaa hh:mm") -> 13-11-2023 10:15 | D20: 0 | E20: 0 | F20: =G19-G20 -> 280.29 | G20: 938.96 | I20: 1 | J20: =56.6*77.9/100 -> 44.0914 | K20: =J20*$K$2 -> 67.459842 | L20: =267.7*95.9/100*$L$2 -> 323.47262 | M20: =72.8*85.1/100*$M$2 -> 80.53864 | N20: =K20*D20/1000 -> 0 | O20: =L20*E20/1000 -> 0 | P20: =M20*F20/1000 -> 22.574175 | Q20: =SUM(N20:P20) -> 22.574175 | R20: =TIMEVALUE(C20) -> 0.42708333 | S20: =DATEVALUE(A20)-MIN($A$3:$A$68) -> 45243 | T20: =R20*86400 -> 36900 | U20: =S20-MIN($S$3:$S$68) -> 21 | V20: =U20*86400 -> 1814400 | W20: =V20+T20 -> 1851300 | X20: =W20-$R$2 -> 1631700 | Y20: =E20 -> 0 | Z20: =D20 -> 0
A21: 13/11/2023 | B21: 10:15 | C21: =TEXT(DATEVALUE(A21) + TIMEVALUE(B21), "gg-mm-aaaa hh:mm") -> 13-11-2023 10:15 | G21: 1205.8 | J21: =56.6*77.9/100 -> 44.0914 | K21: =J21*$K$2 -> 67.459842 | L21: =267.7*95.9/100*$L$2 -> 323.47262 | M21: =72.8*85.1/100*$M$2 -> 80.53864 | N21: =K21*D21/1000 -> 0 | O21: =L21*E21/1000 -> 0 | P21: =M21*F21/1000 -> 0 | Q21: =SUM(N21:P21) -> 0 | R21: =TIMEVALUE(C21) -> 0.42708333 | S21: =DATEVALUE(A21)-MIN($A$3:$A$68) -> 45243 | T21: =R21*86400 -> 36900 | U21: =S21-MIN($S$3:$S$68) -> 21 | V21: =U21*86400 -> 1814400 | W21: =V21+T21 -> 1851300 | X21: =W21-$R$2 -> 1631700 | Y21: =E21 -> 0 | Z21: =D21 -> 0
A22: 13/11/2023 | B22: 12:30 | C22: =TEXT(DATEVALUE(A22) + TIMEVALUE(B22), "gg-mm-aaaa hh:mm") -> 13-11-2023 12:30 | D22: =243*2 -> 486 | E22: =61*2 -> 122 | F22: 0 | I22: 1 | J22: =56.6*77.9/100 -> 44.0914 | K22: =J22*$K$2 -> 67.459842 | L22: =267.7*95.9/100*$L$2 -> 323.47262 | M22: =72.8*85.1/100*$M$2 -> 80.53864 | N22: =K22*D22/1000 -> 32.785483 | O22: =L22*E22/1000 -> 39.463659 | P22: =M22*F22/1000 -> 0 | Q22: =SUM(N22:P22) -> 72.249143 | R22: =TIMEVALUE(C22) -> 0.52083333 | S22: =DATEVALUE(A22)-MIN($A$3:$A$68) -> 45243 | T22: =R22*86400 -> 45000 | U22: =S22-MIN($S$3:$S$68) -> 21 | V22: =U22*86400 -> 1814400 | W22: =V22+T22 -> 1859400 | X22: =W22-$R$2 -> 1639800 | Y22: =E22 -> 122 | Z22: =D22 -> 486
A23: 15/11/2023 | B23: 10:00 | C23: =TEXT(DATEVALUE(A23) + TIMEVALUE(B23), "gg-mm-aaaa hh:mm") -> 15-11-2023 10:00 | D23: 0 | E23: 0 | F23: =G21-G23 -> 180.77 | G23: 1025.03 | I23: 1 | J23: =54.9*77.7/100 -> 42.6573 | K23: =J23*$K$2 -> 65.265669 | L23: =267.7*95.9/100*$L$2 -> 323.47262 | M23: =72.8*85.1/100*$M$2 -> 80.53864 | N23: =K23*D23/1000 -> 0 | O23: =L23*E23/1000 -> 0 | P23: =M23*F23/1000 -> 14.55897 | Q23: =SUM(N23:P23) -> 14.55897 | R23: =TIMEVALUE(C23) -> 0.41666667 | S23: =DATEVALUE(A23)-MIN($A$3:$A$68) -> 45245 | T23: =R23*86400 -> 36000 | U23: =S23-MIN($S$3:$S$68) -> 23 | V23: =U23*86400 -> 1987200 | W23: =V23+T23 -> 2023200 | X23: =W23-$R$2 -> 1803600 | Y23: =E23 -> 0 | Z23: =D23 -> 0
A24: 15/11/2023 | B24: 10:00 | C24: =TEXT(DATEVALUE(A24) + TIMEVALUE(B24), "gg-mm-aaaa hh:mm") -> 15-11-2023 10:00 | G24: 1019.85 | J24: =54.9*77.7/100 -> 42.6573 | K24: =J24*$K$2 -> 65.265669 | L24: =267.7*95.9/100*$L$2 -> 323.47262 | M24: =72.8*85.1/100*$M$2 -> 80.53864 | N24: =K24*D24/1000 -> 0 | O24: =L24*E24/1000 -> 0 | P24: =M24*F24/1000 -> 0 | Q24: =SUM(N24:P24) -> 0 | R24: =TIMEVALUE(C24) -> 0.41666667 | S24: =DATEVALUE(A24)-MIN($A$3:$A$68) -> 45245 | T24: =R24*86400 -> 36000 | U24: =S24-MIN($S$3:$S$68) -> 23 | V24: =U24*86400 -> 1987200 | W24: =V24+T24 -> 2023200 | X24: =W24-$R$2 -> 1803600 | Y24: =E24 -> 0 | Z24: =D24 -> 0
A25: 15/11/2023 | B25: 13:00 | C25: =TEXT(DATEVALUE(A25) + TIMEVALUE(B25), "gg-mm-aaaa hh:mm") -> 15-11-2023 13:00 | D25: =243*2 -> 486 | E25: =61*2 -> 122 | F25: 0 | H25: I closed the valve to the main gas bag and opened the one to the reserve one. No spike in ritter. | I25: 1 | J25: =54.9*77.7/100 -> 42.6573 | K25: =J25*$K$2 -> 65.265669 | L25: =267.7*95.9/100*$L$2 -> 323.47262 | M25: =72.8*85.1/100*$M$2 -> 80.53864 | N25: =K25*D25/1000 -> 31.719115 | O25: =L25*E25/1000 -> 39.463659 | P25: =M25*F25/1000 -> 0 | Q25: =SUM(N25:P25) -> 71.182775 | R25: =TIMEVALUE(C25) -> 0.54166667 | S25: =DATEVALUE(A25)-MIN($A$3:$A$68) -> 45245 | T25: =R25*86400 -> 46800 | U25: =S25-MIN($S$3:$S$68) -> 23 | V25: =U25*86400 -> 1987200 | W25: =V25+T25 -> 2034000 | X25: =W25-$R$2 -> 1814400 | Y25: =E25 -> 122 | Z25: =D25 -> 486
A26: 17/11/2023 | B26: 09:15 | C26: =TEXT(DATEVALUE(A26) + TIMEVALUE(B26), "gg-mm-aaaa hh:mm") -> 17-11-2023 09:15 | D26: 730 | E26: 183 | F26: =G24-G26 -> 183.3 | G26: 836.55 | H26: NOTE: this is the weight of the bottle before emptying and cleaning | I26: 1 | J26: =54.9*77.7/100 -> 42.6573 | K26: =J26*$K$2 -> 65.265669 | L26: =267.7*95.9/100*$L$2 -> 323.47262 | M26: =72.8*85.1/100*$M$2 -> 80.53864 | N26: =K26*D26/1000 -> 47.643938 | O26: =L26*E26/1000 -> 59.195489 | P26: =M26*F26/1000 -> 14.762733 | Q26: =SUM(N26:P26) -> 121.60216 | R26: =TIMEVALUE(C26) -> 0.38541667 | S26: =DATEVALUE(A26)-MIN($A$3:$A$68) -> 45247 | T26: =R26*86400 -> 33300 | U26: =S26-MIN($S$3:$S$68) -> 25 | V26: =U26*86400 -> 2160000 | W26: =V26+T26 -> 2193300 | X26: =W26-$R$2 -> 1973700 | Y26: =E26 -> 183 | Z26: =D26 -> 730
A27: 17/11/2023 | B27: 09:15 | C27: =TEXT(DATEVALUE(A27) + TIMEVALUE(B27), "gg-mm-aaaa hh:mm") -> 17-11-2023 09:15 | G27: 1229.2 | H27: NOTE: this is the weight of the bottle after emptying, cleaning and disinfecting and refilling with tomato | J27: =54.9*77.7/100 -> 42.6573 | K27: =J27*$K$2 -> 65.265669 | L27: =267.7*95.9/100*$L$2 -> 323.47262 | M27: =72.8*85.1/100*$M$2 -> 80.53864 | N27: =K27*D27/1000 -> 0 | O27: =L27*E27/1000 -> 0 | P27: =M27*F27/1000 -> 0 | Q27: =SUM(N27:P27) -> 0 | R27: =TIMEVALUE(C27) -> 0.38541667 | S27: =DATEVALUE(A27)-MIN($A$3:$A$68) -> 45247 | T27: =R27*86400 -> 33300 | U27: =S27-MIN($S$3:$S$68) -> 25 | V27: =U27*86400 -> 2160000 | W27: =V27+T27 -> 2193300 | X27: =W27-$R$2 -> 1973700 | Y27: =E27 -> 0 | Z27: =D27 -> 0
A28: 20/11/2023 | B28: 10:20 | C28: =TEXT(DATEVALUE(A28) + TIMEVALUE(B28), "gg-mm-aaaa hh:mm") -> 20-11-2023 10:20 | D28: 0 | E28: 0 | F28: =G27-G28 -> 270.34 | G28: 958.86 | I28: 1 | J28: =54.9*77.7/100 -> 42.6573 | K28: =J28*$K$2 -> 65.265669 | L28: =267.7*95.9/100*$L$2 -> 323.47262 | M28: =72.8*85.1/100*$M$2 -> 80.53864 | N28: =K28*D28/1000 -> 0 | O28: =L28*E28/1000 -> 0 | P28: =M28*F28/1000 -> 21.772816 | Q28: =SUM(N28:P28) -> 21.772816 | R28: =TIMEVALUE(C28) -> 0.43055556 | S28: =DATEVALUE(A28)-MIN($A$3:$A$68) -> 45250 | T28: =R28*86400 -> 37200 | U28: =S28-MIN($S$3:$S$68) -> 28 | V28: =U28*86400 -> 2419200 | W28: =V28+T28 -> 2456400 | X28: =W28-$R$2 -> 2236800 | Y28: =E28 -> 0 | Z28: =D28 -> 0
A29: 20/11/2023 | B29: 10:20 | C29: =TEXT(DATEVALUE(A29) + TIMEVALUE(B29), "gg-mm-aaaa hh:mm") -> 20-11-2023 10:20 | G29: 1081.5 | J29: =54.9*77.7/100 -> 42.6573 | K29: =J29*$K$2 -> 65.265669 | L29: =267.7*95.9/100*$L$2 -> 323.47262 | M29: =72.8*85.1/100*$M$2 -> 80.53864 | N29: =K29*D29/1000 -> 0 | O29: =L29*E29/1000 -> 0 | P29: =M29*F29/1000 -> 0 | Q29: =SUM(N29:P29) -> 0 | R29: =TIMEVALUE(C29) -> 0.43055556 | S29: =DATEVALUE(A29)-MIN($A$3:$A$68) -> 45250 | T29: =R29*86400 -> 37200 | U29: =S29-MIN($S$3:$S$68) -> 28 | V29: =U29*86400 -> 2419200 | W29: =V29+T29 -> 2456400 | X29: =W29-$R$2 -> 2236800 | Y29: =E29 -> 0 | Z29: =D29 -> 0
A30: 20/11/2023 | B30: 12:00 | C30: =TEXT(DATEVALUE(A30) + TIMEVALUE(B30), "gg-mm-aaaa hh:mm") -> 20-11-2023 12:00 | D30: =243*2 -> 486 | E30: =61*2 -> 122 | F30: 0 | I30: 1 | J30: =54.9*77.7/100 -> 42.6573 | K30: =J30*$K$2 -> 65.265669 | L30: =267.7*95.9/100*$L$2 -> 323.47262 | M30: =72.8*85.1/100*$M$2 -> 80.53864 | N30: =K30*D30/1000 -> 31.719115 | O30: =L30*E30/1000 -> 39.463659 | P30: =M30*F30/1000 -> 0 | Q30: =SUM(N30:P30) -> 71.182775 | R30: =TIMEVALUE(C30) -> 0.5 | S30: =DATEVALUE(A30)-MIN($A$3:$A$68) -> 45250 | T30: =R30*86400 -> 43200 | U30: =S30-MIN($S$3:$S$68) -> 28 | V30: =U30*86400 -> 2419200 | W30: =V30+T30 -> 2462400 | X30: =W30-$R$2 -> 2242800 | Y30: =E30 -> 122 | Z30: =D30 -> 486
A31: 22/11/2023 | B31: 10:00 | C31: =TEXT(DATEVALUE(A31) + TIMEVALUE(B31), "gg-mm-aaaa hh:mm") -> 22-11-2023 10:00 | D31: 0 | E31: 0 | F31: =G29-G31 -> 173.34 | G31: 908.16 | I31: 1 | J31: =54.9*77.7/100 -> 42.6573 | K31: =J31*$K$2 -> 65.265669 | L31: =267.7*95.9/100*$L$2 -> 323.47262 | M31: =72.8*85.1/100*$M$2 -> 80.53864 | N31: =K31*D31/1000 -> 0 | O31: =L31*E31/1000 -> 0 | P31: =M31*F31/1000 -> 13.960568 | Q31: =SUM(N31:P31) -> 13.960568 | R31: =TIMEVALUE(C31) -> 0.41666667 | S31: =DATEVALUE(A31)-MIN($A$3:$A$68) -> 45252 | T31: =R31*86400 -> 36000 | U31: =S31-MIN($S$3:$S$68) -> 30 | V31: =U31*86400 -> 2592000 | W31: =V31+T31 -> 2628000 | X31: =W31-$R$2 -> 2408400 | Y31: =E31 -> 0 | Z31: =D31 -> 0
A32: 22/11/2023 | B32: 10:00 | C32: =TEXT(DATEVALUE(A32) + TIMEVALUE(B32), "gg-mm-aaaa hh:mm") -> 22-11-2023 10:00 | G32: 1112.72 | J32: =54.9*77.7/100 -> 42.6573 | K32: =J32*$K$2 -> 65.265669 | L32: =267.7*95.9/100*$L$2 -> 323.47262 | M32: =72.8*85.1/100*$M$2 -> 80.53864 | N32: =K32*D32/1000 -> 0 | O32: =L32*E32/1000 -> 0 | P32: =M32*F32/1000 -> 0 | Q32: =SUM(N32:P32) -> 0 | R32: =TIMEVALUE(C32) -> 0.41666667 | S32: =DATEVALUE(A32)-MIN($A$3:$A$68) -> 45252 | T32: =R32*86400 -> 36000 | U32: =S32-MIN($S$3:$S$68) -> 30 | V32: =U32*86400 -> 2592000 | W32: =V32+T32 -> 2628000 | X32: =W32-$R$2 -> 2408400 | Y32: =E32 -> 0 | Z32: =D32 -> 0
A33: 22/11/2023 | B33: 13:00 | C33: =TEXT(DATEVALUE(A33) + TIMEVALUE(B33), "gg-mm-aaaa hh:mm") -> 22-11-2023 13:00 | D33: =243*2 -> 486 | E33: =61*2 -> 122 | F33: 0 | I33: 1 | J33: =54.9*77.7/100 -> 42.6573 | K33: =J33*$K$2 -> 65.265669 | L33: =267.7*95.9/100*$L$2 -> 323.47262 | M33: =72.8*85.1/100*$M$2 -> 80.53864 | N33: =K33*D33/1000 -> 31.719115 | O33: =L33*E33/1000 -> 39.463659 | P33: =M33*F33/1000 -> 0 | Q33: =SUM(N33:P33) -> 71.182775 | R33: =TIMEVALUE(C33) -> 0.54166667 | S33: =DATEVALUE(A33)-MIN($A$3:$A$68) -> 45252 | T33: =R33*86400 -> 46800 | U33: =S33-MIN($S$3:$S$68) -> 30 | V33: =U33*86400 -> 2592000 | W33: =V33+T33 -> 2638800 | X33: =W33-$R$2 -> 2419200 | Y33: =E33 -> 122 | Z33: =D33 -> 486
A34: 24/11/2023 | B34: 09:20 | C34: =TEXT(DATEVALUE(A34) + TIMEVALUE(B34), "gg-mm-aaaa hh:mm") -> 24-11-2023 09:20 | D34: 0 | E34: 0 | F34: =(G32-G34) -> 211.74 | G34: 900.98 | H34: NOTE: this is the weight of the bottle before emptying and cleaning | I34: 1 | J34: =54.9*77.7/100 -> 42.6573 | K34: =J34*$K$2 -> 65.265669 | L34: =267.7*95.9/100*$L$2 -> 323.47262 | M34: =72.8*85.1/100*$M$2 -> 80.53864 | N34: =K34*D34/1000 -> 0 | O34: =L34*E34/1000 -> 0 | P34: =M34*F34/1000 -> 17.053252 | Q34: =SUM(N34:P34) -> 17.053252 | R34: =TIMEVALUE(C34) -> 0.38888889 | S34: =DATEVALUE(A34)-MIN($A$3:$A$68) -> 45254 | T34: =R34*86400 -> 33600 | U34: =S34-MIN($S$3:$S$68) -> 32 | V34: =U34*86400 -> 2764800 | W34: =V34+T34 -> 2798400 | X34: =W34-$R$2 -> 2578800 | Y34: =E34 -> 0 | Z34: =D34 -> 0
A35: 24/11/2023 | B35: 10:30 | C35: =TEXT(DATEVALUE(A35) + TIMEVALUE(B35), "gg-mm-aaaa hh:mm") -> 24-11-2023 10:30 | G35: 1207.31 | H35: NOTE: this is the weight of the bottle after emptying, cleaning and disinfecting and refilling with tomato. ariana was responsible for this part it was around 10:30 I guess | J35: =54.9*77.7/100 -> 42.6573 | K35: =J35*$K$2 -> 65.265669 | L35: =267.7*95.9/100*$L$2 -> 323.47262 | M35: =72.8*85.1/100*$M$2 -> 80.53864 | N35: =K35*D35/1000 -> 0 | O35: =L35*E35/1000 -> 0 | P35: =M35*F35/1000 -> 0 | Q35: =SUM(N35:P35) -> 0 | R35: =TIMEVALUE(C35) -> 0.4375 | S35: =DATEVALUE(A35)-MIN($A$3:$A$68) -> 45254 | T35: =R35*86400 -> 37800 | U35: =S35-MIN($S$3:$S$68) -> 32 | V35: =U35*86400 -> 2764800 | W35: =V35+T35 -> 2802600 | X35: =W35-$R$2 -> 2583000 | Y35: =E35 -> 0 | Z35: =D35 -> 0
A36: 24/11/2023 | B36: 15:10 | C36: =TEXT(DATEVALUE(A36) + TIMEVALUE(B36), "gg-mm-aaaa hh:mm") -> 24-11-2023 15:10 | D36: 730 | E36: 183 | F36: 0 | I36: 1 | J36: =54.9*77.7/100 -> 42.6573 | K36: =J36*$K$2 -> 65.265669 | L36: =267.7*95.9/100*$L$2 -> 323.47262 | M36: =72.8*85.1/100*$M$2 -> 80.53864 | N36: =K36*D36/1000 -> 47.643938 | O36: =L36*E36/1000 -> 59.195489 | P36: =M36*F36/1000 -> 0 | Q36: =SUM(N36:P36) -> 106.83943 | R36: =TIMEVALUE(C36) -> 0.63194444 | S36: =DATEVALUE(A36)-MIN($A$3:$A$68) -> 45254 | T36: =R36*86400 -> 54600 | U36: =S36-MIN($S$3:$S$68) -> 32 | V36: =U36*86400 -> 2764800 | W36: =V36+T36 -> 2819400 | X36: =W36-$R$2 -> 2599800 | Y36: =E36 -> 183 | Z36: =D36 -> 730
A37: 27/11/2023 | B37: 10:00 | C37: =TEXT(DATEVALUE(A37) + TIMEVALUE(B37), "gg-mm-aaaa hh:mm") -> 27-11-2023 10:00 | D37: 0 | E37: 0 | F37: =G35-G37 -> 271.22 | G37: 936.09 | I37: 1 | J37: =54.9*77.7/100 -> 42.6573 | K37: =J37*$K$2 -> 65.265669 | L37: =267.7*95.9/100*$L$2 -> 323.47262 | M37: =72.8*85.1/100*$M$2 -> 80.53864 | N37: =K37*D37/1000 -> 0 | O37: =L37*E37/1000 -> 0 | P37: =M37*F37/1000 -> 21.84369 | Q37: =SUM(N37:P37) -> 21.84369 | R37: =TIMEVALUE(C37) -> 0.41666667 | S37: =DATEVALUE(A37)-MIN($A$3:$A$68) -> 45257 | T37: =R37*86400 -> 36000 | U37: =S37-MIN($S$3:$S$68) -> 35 | V37: =U37*86400 -> 3024000 | W37: =V37+T37 -> 3060000 | X37: =W37-$R$2 -> 2840400 | Y37: =E37 -> 0 | Z37: =D37 -> 0
A38: 27/11/2023 | B38: 10:00 | C38: =TEXT(DATEVALUE(A38) + TIMEVALUE(B38), "gg-mm-aaaa hh:mm") -> 27-11-2023 10:00 | G38: 1118.21 | J38: =54.9*77.7/100 -> 42.6573 | K38: =J38*$K$2 -> 65.265669 | L38: =267.7*95.9/100*$L$2 -> 323.47262 | M38: =72.8*85.1/100*$M$2 -> 80.53864 | N38: =K38*D38/1000 -> 0 | O38: =L38*E38/1000 -> 0 | P38: =M38*F38/1000 -> 0 | Q38: =SUM(N38:P38) -> 0 | R38: =TIMEVALUE(C38) -> 0.41666667 | S38: =DATEVALUE(A38)-MIN($A$3:$A$68) -> 45257 | T38: =R38*86400 -> 36000 | U38: =S38-MIN($S$3:$S$68) -> 35 | V38: =U38*86400 -> 3024000 | W38: =V38+T38 -> 3060000 | X38: =W38-$R$2 -> 2840400 | Y38: =E38 -> 0 | Z38: =D38 -> 0
A39: 27/11/2023 | B39: 13:00 | C39: =TEXT(DATEVALUE(A39) + TIMEVALUE(B39), "gg-mm-aaaa hh:mm") -> 27-11-2023 13:00 | D39: =243*2 -> 486 | E39: =61*2 -> 122 | F39: 0 | I39: 1 | J39: =54.9*77.7/100 -> 42.6573 | K39: =J39*$K$2 -> 65.265669 | L39: =267.7*95.9/100*$L$2 -> 323.47262 | M39: =72.8*85.1/100*$M$2 -> 80.53864 | N39: =K39*D39/1000 -> 31.719115 | O39: =L39*E39/1000 -> 39.463659 | P39: =M39*F39/1000 -> 0 | Q39: =SUM(N39:P39) -> 71.182775 | R39: =TIMEVALUE(C39) -> 0.54166667 | S39: =DATEVALUE(A39)-MIN($A$3:$A$68) -> 45257 | T39: =R39*86400 -> 46800 | U39: =S39-MIN($S$3:$S$68) -> 35 | V39: =U39*86400 -> 3024000 | W39: =V39+T39 -> 3070800 | X39: =W39-$R$2 -> 2851200 | Y39: =E39 -> 122 | Z39: =D39 -> 486
A40: 29/11/2023 | B40: 10:00 | C40: =TEXT(DATEVALUE(A40) + TIMEVALUE(B40), "gg-mm-aaaa hh:mm") -> 29-11-2023 10:00 | D40: 0 | E40: 0 | F40: =G38-G40 -> 189.04 | G40: 929.17 | I40: 1 | J40: =54.9*77.7/100 -> 42.6573 | K40: =J40*$K$2 -> 65.265669 | L40: =267.7*95.9/100*$L$2 -> 323.47262 | M40: =72.8*85.1/100*$M$2 -> 80.53864 | N40: =K40*D40/1000 -> 0 | O40: =L40*E40/1000 -> 0 | P40: =M40*F40/1000 -> 15.225025 | Q40: =SUM(N40:P40) -> 15.225025 | R40: =TIMEVALUE(C40) -> 0.41666667 | S40: =DATEVALUE(A40)-MIN($A$3:$A$68) -> 45259 | T40: =R40*86400 -> 36000 | U40: =S40-MIN($S$3:$S$68) -> 37 | V40: =U40*86400 -> 3196800 | W40: =V40+T40 -> 3232800 | X40: =W40-$R$2 -> 3013200 | Y40: =E40 -> 0 | Z40: =D40 -> 0
...

Sheet R2 feed
A1: Data | B1: Time | C1: Timestamp | D1: Slurry | E1: Maize | F1: Tomato | G1: Tomato bottle weight | H1: Note | I1: pHs | J1: Slurry VS | K1: Slurry S_COD | L1: Maize S_COD | M1: Tomato S_COD | N1: Slurry COD | O1: Maize COD | P1: Tomato COD | Q1: COD_in | R1: Start Modelica Timestamp
D2: [g] | E2: [g] | F2: [g] | K2: 1.53 | L2: 1.26 | M2: 1.3 | R2: =86400*2+13*3600 -> 219600 | V2: Devo aggiungere 0?
A3: 23/10/2023 | B3: 11:00 | C3: =TEXT(DATEVALUE(A3) + TIMEVALUE(B3), "gg-mm-aaaa hh:mm") -> 23-10-2023 11:00 | D3: =243*2 -> 486 | E3: =61*2 -> 122 | F3: 0 | H3: Betweeen 11:00 and 11:40. Mixture of maize and slurry. Clogging of the channel that has been built to prevent for gas leakages. Maybe better to insert maize silage prior slurry. Today the channel was removed, mixing stopped and the mixture inserted directly in the steel funnel. Probably 1% of the mixture has been lost in dirtiness of tools during injection. Forgot to close gas valve before discharge. I closed it at half of the feeding. | I3: 1 | J3: =66.4*79.5/100 -> 52.788 | K3: =J3*$K$2 -> 80.76564 | L3: =267.7*95.9/100*$L$2 -> 323.47262 | M3: =72.8*85.1/100*$M$2 -> 80.53864 | N3: =K3*D3/1000 -> 39.252101 | O3: =L3*E3/1000 -> 39.463659 | P3: =M3*F3/1000 -> 0 | Q3: =SUM(N3:P3) -> 78.71576 | R3: =TIMEVALUE(C3) -> 0.45833333 | S3: =DATEVALUE(A3)-MIN($A$3:$A$68) -> 45222 | T3: =R3*86400 -> 39600 | U3: =S3-MIN($S$3:$S$68) -> 0 | V3: =U3*86400 -> 0 | W3: =V3+T3 -> 39600 | X3: =W3-$R$2 -> -180000 | Y3: =E3 -> 122 | Z3: =D3 -> 486 | AA3: 96
A4: 23/10/2023 | B4: 11:00 | C4: =TEXT(DATEVALUE(A4) + TIMEVALUE(B4), "gg-mm-aaaa hh:mm") -> 23-10-2023 11:00 | J4: =66.4*79.5/100 -> 52.788 | K4: =J4*$K$2 -> 80.76564 | L4: =267.7*95.9/100*$L$2 -> 323.47262 | M4: =72.8*85.1/100*$M$2 -> 80.53864 | N4: =K4*D4/1000 -> 0 | O4: =L4*E4/1000 -> 0 | P4: =M4*F4/1000 -> 0 | Q4: =SUM(N4:P4) -> 0 | R4: =TIMEVALUE(C4) -> 0.45833333 | S4: =DATEVALUE(A4)-MIN($A$3:$A$68) -> 45222 | T4: =R4*86400 -> 39600 | U4: =S4-MIN($S$3:$S$68) -> 0 | V4: =U4*86400 -> 0 | W4: =V4+T4 -> 39600 | X4: =W4-$R$2 -> -180000 | Y4: =E4 -> 0 | Z4: =D4 -> 0 | AA4: 96
A5: 25/10/2023 | B5: 11:15 | C5: =TEXT(DATEVALUE(A5) + TIMEVALUE(B5), "gg-mm-aaaa hh:mm") -> 25-10-2023 11:15 | D5: =243*2 -> 486 | E5: =61*2 -> 122 | F5: 0 | H5: Closed the valve but still peaks | I5: 1 | J5: =66.4*79.5/100 -> 52.788 | K5: =J5*$K$2 -> 80.76564 | L5: =267.7*95.9/100*$L$2 -> 323.47262 | M5: =72.8*85.1/100*$M$2 -> 80.53864 | N5: =K5*D5/1000 -> 39.252101 | O5: =L5*E5/1000 -> 39.463659 | P5: =M5*F5/1000 -> 0 | Q5: =SUM(N5:P5) -> 78.71576 | R5: =TIMEVALUE(C5) -> 0.46875 | S5: =DATEVALUE(A5)-MIN($A$3:$A$68) -> 45224 | T5: =R5*86400 -> 40500 | U5: =S5-MIN($S$3:$S$68) -> 2 | V5: =U5*86400 -> 172800 | W5: =V5+T5 -> 213300 | X5: =W5-$R$2 -> -6300 | Y5: =E5 -> 122 | Z5: =D5 -> 486 | AA5: 96
A6: 25/10/2023 | B6: 12:07 | C6: =TEXT(DATEVALUE(A6) + TIMEVALUE(B6), "gg-mm-aaaa hh:mm") -> 25-10-2023 12:07 | F6: 0 | H6: Start tomato sauce at 12:07. Bottle of tomato of 600 mL. Set for 6 second every 15 minutes > 4 feedings until 13:07 (96 mL/day). Changed it to 1 min/2.5hours (see notebook for reason). Start weight of the bottle 1280.86 g | J6: =66.4*79.5/100 -> 52.788 | K6: =J6*$K$2 -> 80.76564 | L6: =267.7*95.9/100*$L$2 -> 323.47262 | M6: =72.8*85.1/100*$M$2 -> 80.53864 | N6: =K6*D6/1000 -> 0 | O6: =L6*E6/1000 -> 0 | P6: =M6*F6/1000 -> 0 | Q6: =SUM(N6:P6) -> 0 | R6: =TIMEVALUE(C6) -> 0.50486111 | S6: =DATEVALUE(A6)-MIN($A$3:$A$68) -> 45224 | T6: =R6*86400 -> 43620 | U6: =S6-MIN($S$3:$S$68) -> 2 | V6: =U6*86400 -> 172800 | W6: =V6+T6 -> 216420 | X6: =W6-$R$2 -> -3180 | Y6: =E6 -> 0 | Z6: =D6 -> 0 | AA6: 96
A7: 25/10/2023 | B7: 13:07 | C7: =TEXT(DATEVALUE(A7) + TIMEVALUE(B7), "gg-mm-aaaa hh:mm") -> 25-10-2023 13:07 | F7: =6*4*0.16666667 -> 4.0000001 | J7: =66.4*79.5/100 -> 52.788 | K7: =J7*$K$2 -> 80.76564 | L7: =267.7*95.9/100*$L$2 -> 323.47262 | M7: =72.8*85.1/100*$M$2 -> 80.53864 | N7: =K7*D7/1000 -> 0 | O7: =L7*E7/1000 -> 0 | P7: =M7*F7/1000 -> 0.32215457 | Q7: =SUM(N7:P7) -> 0.32215457 | R7: =TIMEVALUE(C7) -> 0.54652778 | S7: =DATEVALUE(A7)-MIN($A$3:$A$68) -> 45224 | T7: =R7*86400 -> 47220 | U7: =S7-MIN($S$3:$S$68) -> 2 | V7: =U7*86400 -> 172800 | W7: =V7+T7 -> 220020 | X7: =W7-$R$2 -> 420 | Y7: =E7 -> 0 | Z7: =D7 -> 0 | AA7: 96
A8: 25/10/2023 | B8: 13:30 | C8: =TEXT(DATEVALUE(A8) + TIMEVALUE(B8), "gg-mm-aaaa hh:mm") -> 25-10-2023 13:30 | F8: =10 -> 10 | H8: Erronous small feed becouse pumps started when switched from steady to automatic (I wanted to guarantee mixing right after the feeding): around 5 mL | J8: =66.4*79.5/100 -> 52.788 | K8: =J8*$K$2 -> 80.76564 | L8: =267.7*95.9/100*$L$2 -> 323.47262 | M8: =72.8*85.1/100*$M$2 -> 80.53864 | N8: =K8*D8/1000 -> 0 | O8: =L8*E8/1000 -> 0 | P8: =M8*F8/1000 -> 0.8053864 | Q8: =SUM(N8:P8) -> 0.8053864 | R8: =TIMEVALUE(C8) -> 0.5625 | S8: =DATEVALUE(A8)-MIN($A$3:$A$68) -> 45224 | T8: =R8*86400 -> 48600 | U8: =S8-MIN($S$3:$S$68) -> 2 | V8: =U8*86400 -> 172800 | W8: =V8+T8 -> 221400 | X8: =W8-$R$2 -> 1800 | Y8: =E8 -> 0 | Z8: =D8 -> 0 | AA8: 96
A9: 25/10/2023 | B9: 13:40 | C9: =TEXT(DATEVALUE(A9) + TIMEVALUE(B9), "gg-mm-aaaa hh:mm") -> 25-10-2023 13:40 | F9: =5 -> 5 | J9: =66.4*79.5/100 -> 52.788 | K9: =J9*$K$2 -> 80.76564 | L9: =267.7*95.9/100*$L$2 -> 323.47262 | M9: =72.8*85.1/100*$M$2 -> 80.53864 | N9: =K9*D9/1000 -> 0 | O9: =L9*E9/1000 -> 0 | P9: =M9*F9/1000 -> 0.4026932 | Q9: =SUM(N9:P9) -> 0.4026932 | R9: =TIMEVALUE(C9) -> 0.56944444 | S9: =DATEVALUE(A9)-MIN($A$3:$A$68) -> 45224 | T9: =R9*86400 -> 49200 | U9: =S9-MIN($S$3:$S$68) -> 2 | V9: =U9*86400 -> 172800 | W9: =V9+T9 -> 222000 | X9: =W9-$R$2 -> 2400 | Y9: =E9 -> 0 | Z9: =D9 -> 0 | AA9: 96
A10: 25/10/2023 | B10: 15:03 | C10: =TEXT(DATEVALUE(A10) + TIMEVALUE(B10), "gg-mm-aaaa hh:mm") -> 25-10-2023 15:03 | F10: =60*0.166667 -> 10.00002 | J10: =66.4*79.5/100 -> 52.788 | K10: =J10*$K$2 -> 80.76564 | L10: =267.7*95.9/100*$L$2 -> 323.47262 | M10: =72.8*85.1/100*$M$2 -> 80.53864 | N10: =K10*D10/1000 -> 0 | O10: =L10*E10/1000 -> 0 | P10: =M10*F10/1000 -> 0.80538801 | Q10: =SUM(N10:P10) -> 0.80538801 | R10: =TIMEVALUE(C10) -> 0.62708333 | S10: =DATEVALUE(A10)-MIN($A$3:$A$68) -> 45224 | T10: =R10*86400 -> 54180 | U10: =S10-MIN($S$3:$S$68) -> 2 | V10: =U10*86400 -> 172800 | W10: =V10+T10 -> 226980 | X10: =W10-$R$2 -> 7380 | Y10: =E10 -> 0 | Z10: =D10 -> 0 | AA10: 96
A11: 25/10/2023 | B11: 16:33 | C11: =TEXT(DATEVALUE(A11) + TIMEVALUE(B11), "gg-mm-aaaa hh:mm") -> 25-10-2023 16:33 | F11: =60*0.166667 -> 10.00002 | H11: I set it wrong: 1 min/1.5 hours. Now modified. From now on R1 and R2 are going to be mixed and fed with tomato almost at the same timestamp | J11: =66.4*79.5/100 -> 52.788 | K11: =J11*$K$2 -> 80.76564 | L11: =267.7*95.9/100*$L$2 -> 323.47262 | M11: =72.8*85.1/100*$M$2 -> 80.53864 | N11: =K11*D11/1000 -> 0 | O11: =L11*E11/1000 -> 0 | P11: =M11*F11/1000 -> 0.80538801 | Q11: =SUM(N11:P11) -> 0.80538801 | R11: =TIMEVALUE(C11) -> 0.68958333 | S11: =DATEVALUE(A11)-MIN($A$3:$A$68) -> 45224 | T11: =R11*86400 -> 59580 | U11: =S11-MIN($S$3:$S$68) -> 2 | V11: =U11*86400 -> 172800 | W11: =V11+T11 -> 232380 | X11: =W11-$R$2 -> 12780 | Y11: =E11 -> 0 | Z11: =D11 -> 0 | AA11: 96
A12: 27/10/2023 | B12: 10:50 | C12: =TEXT(DATEVALUE(A12) + TIMEVALUE(B12), "gg-mm-aaaa hh:mm") -> 27-10-2023 10:50 | D12: 730 | E12: 183 | F12: 0 | H12: we didnt feed the tomato bottle since the level was above 300ml | I12: 1 | J12: =66.4*79.5/100 -> 52.788 | K12: =J12*$K$2 -> 80.76564 | L12: =267.7*95.9/100*$L$2 -> 323.47262 | M12: =72.8*85.1/100*$M$2 -> 80.53864 | N12: =K12*D12/1000 -> 58.958917 | O12: =L12*E12/1000 -> 59.195489 | P12: =M12*F12/1000 -> 0 | Q12: =SUM(N12:P12) -> 118.15441 | R12: =TIMEVALUE(C12) -> 0.45138889 | S12: =DATEVALUE(A12)-MIN($A$3:$A$68) -> 45226 | T12: =R12*86400 -> 39000 | U12: =S12-MIN($S$3:$S$68) -> 4 | V12: =U12*86400 -> 345600 | W12: =V12+T12 -> 384600 | X12: =W12-$R$2 -> 165000 | Y12: =E12 -> 183 | Z12: =D12 -> 730 | AA12: 96
A13: 30/10/2023 | B13: 11:15 | C13: =TEXT(DATEVALUE(A13) + TIMEVALUE(B13), "gg-mm-aaaa hh:mm") -> 30-10-2023 11:15 | F13: ? | H13: Acetate spike fed with pumps (480 mL of 50gCOD/L solution). Forgot to weight tomato bottle…MOLD! Pump tubes were not sucking anymore, too low level (don't go below 100 mL) | J13: =66.4*79.5/100 -> 52.788 | K13: =J13*$K$2 -> 80.76564 | L13: =267.7*95.9/100*$L$2 -> 323.47262 | M13: =72.8*85.1/100*$M$2 -> 80.53864 | N13: =K13*D13/1000 -> 0 | O13: =L13*E13/1000 -> 0 | P13: =M13*F13/1000 -> #VALUE! | Q13: =SUM(N13:P13) -> #VALUE! | R13: =TIMEVALUE(C13) -> 0.46875 | S13: =DATEVALUE(A13)-MIN($A$3:$A$68) -> 45229 | T13: =R13*86400 -> 40500 | U13: =S13-MIN($S$3:$S$68) -> 7 | V13: =U13*86400 -> 604800 | W13: =V13+T13 -> 645300 | X13: =W13-$R$2 -> 425700 | Y13: =E13 -> 0 | Z13: =D13 -> 0 | AA13: 96
A14: 03/11/2023 | B14: 10:15 | C14: =TEXT(DATEVALUE(A14) + TIMEVALUE(B14), "gg-mm-aaaa hh:mm") -> 03-11-2023 10:15 | D14: 730 | E14: 183 | F14: 0 | G14: 1143.36 | H14: weight of empty clean tomato bottle:.... FORGOT TO WEIGH IT. the weight of tomato bottle after filling: 1143,36g. PLEASE NOTE that we didnt write down the exact time for feeding but it was between 10:00 ana 10:30 | I14: 1 | J14: =56.6*77.9/100 -> 44.0914 | K14: =J14*$K$2 -> 67.459842 | L14: =267.7*95.9/100*$L$2 -> 323.47262 | M14: =72.8*85.1/100*$M$2 -> 80.53864 | N14: =K14*D14/1000 -> 49.245685 | O14: =L14*E14/1000 -> 59.195489 | P14: =M14*F14/1000 -> 0 | Q14: =SUM(N14:P14) -> 108.44117 | R14: =TIMEVALUE(C14) -> 0.42708333 | S14: =DATEVALUE(A14)-MIN($A$3:$A$68) -> 45233 | T14: =R14*86400 -> 36900 | U14: =S14-MIN($S$3:$S$68) -> 11 | V14: =U14*86400 -> 950400 | W14: =V14+T14 -> 987300 | X14: =W14-$R$2 -> 767700 | Y14: =E14 -> 183 | Z14: =D14 -> 730 | AA14: 96
A15: 06/11/2023 | B15: 10:00 | C15: =TEXT(DATEVALUE(A15) + TIMEVALUE(B15), "gg-mm-aaaa hh:mm") -> 06-11-2023 10:00 | D15: 0 | E15: 0 | F15: =G14-G15 -> 273.86 | G15: 869.5 | H15: Weight bottle tomato 869.50 g | I15: 1 | J15: =56.6*77.9/100 -> 44.0914 | K15: =J15*$K$2 -> 67.459842 | L15: =267.7*95.9/100*$L$2 -> 323.47262 | M15: =72.8*85.1/100*$M$2 -> 80.53864 | N15: =K15*D15/1000 -> 0 | O15: =L15*E15/1000 -> 0 | P15: =M15*F15/1000 -> 22.056312 | Q15: =SUM(N15:P15) -> 22.056312 | R15: =TIMEVALUE(C15) -> 0.41666667 | S15: =DATEVALUE(A15)-MIN($A$3:$A$68) -> 45236 | T15: =R15*86400 -> 36000 | U15: =S15-MIN($S$3:$S$68) -> 14 | V15: =U15*86400 -> 1209600 | W15: =V15+T15 -> 1245600 | X15: =W15-$R$2 -> 1026000 | Y15: =E15 -> 0 | Z15: =D15 -> 0 | AA15: 96
A16: 06/11/2023 | B16: 10:00 | C16: =TEXT(DATEVALUE(A16) + TIMEVALUE(B16), "gg-mm-aaaa hh:mm") -> 06-11-2023 10:00 | G16: 1269.58 | J16: =56.6*77.9/100 -> 44.0914 | K16: =J16*$K$2 -> 67.459842 | L16: =267.7*95.9/100*$L$2 -> 323.47262 | M16: =72.8*85.1/100*$M$2 -> 80.53864 | N16: =K16*D16/1000 -> 0 | O16: =L16*E16/1000 -> 0 | P16: =M16*F16/1000 -> 0 | Q16: =SUM(N16:P16) -> 0 | R16: =TIMEVALUE(C16) -> 0.41666667 | S16: =DATEVALUE(A16)-MIN($A$3:$A$68) -> 45236 | T16: =R16*86400 -> 36000 | U16: =S16-MIN($S$3:$S$68) -> 14 | V16: =U16*86400 -> 1209600 | W16: =V16+T16 -> 1245600 | X16: =W16-$R$2 -> 1026000 | Y16: =E16 -> 0 | Z16: =D16 -> 0 | AA16: 96
A17: 06/11/2023 | B17: 15:15 | C17: =TEXT(DATEVALUE(A17) + TIMEVALUE(B17), "gg-mm-aaaa hh:mm") -> 06-11-2023 15:15 | D17: =243*2 -> 486 | E17: =61*2 -> 122 | F17: 0 | I17: 1 | J17: =56.6*77.9/100 -> 44.0914 | K17: =J17*$K$2 -> 67.459842 | L17: =267.7*95.9/100*$L$2 -> 323.47262 | M17: =72.8*85.1/100*$M$2 -> 80.53864 | N17: =K17*D17/1000 -> 32.785483 | O17: =L17*E17/1000 -> 39.463659 | P17: =M17*F17/1000 -> 0 | Q17: =SUM(N17:P17) -> 72.249143 | R17: =TIMEVALUE(C17) -> 0.63541667 | S17: =DATEVALUE(A17)-MIN($A$3:$A$68) -> 45236 | T17: =R17*86400 -> 54900 | U17: =S17-MIN($S$3:$S$68) -> 14 | V17: =U17*86400 -> 1209600 | W17: =V17+T17 -> 1264500 | X17: =W17-$R$2 -> 1044900 | Y17: =E17 -> 122 | Z17: =D17 -> 486 | AA17: 96
A18: 08/11/2023 | B18: 11:06 | C18: =TEXT(DATEVALUE(A18) + TIMEVALUE(B18), "gg-mm-aaaa hh:mm") -> 08-11-2023 11:06 | D18: 0 | E18: 0 | F18: =G16-G18 -> 177.28 | G18: 1092.3 | I18: 1 | J18: =56.6*77.9/100 -> 44.0914 | K18: =J18*$K$2 -> 67.459842 | L18: =267.7*95.9/100*$L$2 -> 323.47262 | M18: =72.8*85.1/100*$M$2 -> 80.53864 | N18: =K18*D18/1000 -> 0 | O18: =L18*E18/1000 -> 0 | P18: =M18*F18/1000 -> 14.27789 | Q18: =SUM(N18:P18) -> 14.27789 | R18: =TIMEVALUE(C18) -> 0.4625 | S18: =DATEVALUE(A18)-MIN($A$3:$A$68) -> 45238 | T18: =R18*86400 -> 39960 | U18: =S18-MIN($S$3:$S$68) -> 16 | V18: =U18*86400 -> 1382400 | W18: =V18+T18 -> 1422360 | X18: =W18-$R$2 -> 1202760 | Y18: =E18 -> 0 | Z18: =D18 -> 0 | AA18: 96
A19: 08/11/2023 | B19: 11:06 | C19: =TEXT(DATEVALUE(A19) + TIMEVALUE(B19), "gg-mm-aaaa hh:mm") -> 08-11-2023 11:06 | G19: 1129.25 | J19: =56.6*77.9/100 -> 44.0914 | K19: =J19*$K$2 -> 67.459842 | L19: =267.7*95.9/100*$L$2 -> 323.47262 | M19: =72.8*85.1/100*$M$2 -> 80.53864 | N19: =K19*D19/1000 -> 0 | O19: =L19*E19/1000 -> 0 | P19: =M19*F19/1000 -> 0 | Q19: =SUM(N19:P19) -> 0 | R19: =TIMEVALUE(C19) -> 0.4625 | S19: =DATEVALUE(A19)-MIN($A$3:$A$68) -> 45238 | T19: =R19*86400 -> 39960 | U19: =S19-MIN($S$3:$S$68) -> 16 | V19: =U19*86400 -> 1382400 | W19: =V19+T19 -> 1422360 | X19: =W19-$R$2 -> 1202760 | Y19: =E19 -> 0 | Z19: =D19 -> 0 | AA19: 96
